Workbook
Name Slicer_action: #N/A
Name Slicer_Action1: #N/A
Name Slicer_Category: #N/A

Sheet Dashboard
A1: SUPPLY CHAIN DASHBOARD | W1: SLICERS
Q5: Action | R5: Category | S5: SKU | T5: Profit | U5: Risk Score
Q6: Monitor | R6: High Profit - High Risk | S6: SKU40 | T6: 75049.74 | U6: 193.81
S7: SKU55 | T7: 55943.06 | U7: 195.6
S8: SKU81 | T8: 56338.21 | U8: 99.35
S9: SKU84 | T9: 55024.31 | U9: 290.61
S10: SKU9 | T10: 62680.29 | U10: 219.14
R11: High Profit - High Risk Total | T11: 305035.61 | U11: 998.51
R12: High Profit - Low Risk | S12: SKU32 | T12: 61826.67 | U12: 91.46
S13: SKU52 | T13: 80368.3 | U13: 46.69
S14: SKU58 | T14: 53548.05 | U14: 51.91
S15: SKU80 | T15: 79384.1 | U15: 68.39
S16: SKU95 | T16: 52283.92 | U16: 49.65
R17: High Profit - Low Risk Total | T17: 327411.04 | U17: 308.1
Q18: Monitor Total | T18: 632446.65 | U18: 1306.61
Q19: Scale | R19: High Profit - Low Risk | S19: SKU0 | T19: 55936.78 | U19: 9.06
S20: SKU11 | T20: 86977.93 | U20: 1.1
S21: SKU14 | T21: 55726.46 | U21: 5.94
S22: SKU47 | T22: 87069.35 | U22: 12.94
S23: SKU91 | T23: 56847.32 | U23: 21.28
R24: High Profit - Low Risk Total | T24: 342557.84 | U24: 50.32
Q25: Scale Total | T25: 342557.84 | U25: 50.32
Q26: Drop | R26: High Profit - High Risk | S26: SKU1 | T26: 10881.5 | U26: 266.97
S27: SKU19 | T27: 9473.05 | U27: 123.98
S28: SKU36 | T28: 9402.28 | U28: 197.89
S29: SKU57 | T29: 11105.81 | U29: 100.45
S30: SKU75 | T30: 9807.13 | U30: 111.65
R31: High Profit - High Risk Total | T31: 50669.77 | U31: 800.94
R32: High Profit - Low Risk | S32: SKU13 | T32: 3916.57 | U32: 65.24
S33: SKU39 | T33: 3351.87 | U33: 90.02
S34: SKU4 | T34: 4089.63 | U34: 50.33
S35: SKU8 | T35: 10292.81 | U35: 81.3
S36: SKU86 | T36: 4383.53 | U36: 49.24
R37: High Profit - Low Risk Total | T37: 26034.41 | U37: 336.13
Q38: Drop Total | T38: 76704.18 | U38: 1137.07
Q39: Optimize | R39: High Profit - Low Risk | S39: SKU17 | T39: 10213.01 | U39: 3.37
S40: SKU43 | T40: 6992.51 | U40: 14.52
S41: SKU53 | T41: 7258.28 | U41: 40.9
S42: SKU68 | T42: 6084.58 | U42: 35.7
S43: SKU79 | T43: 11232.92 | U43: 5.14
...

Sheet Analysis
B2: Shipping Lead Time | G2: Supplier Name | L2: Cost Vs Profit | Q2: Risk Tolerance
Y3: Profit Vs Risk_Scenario
AM4: Summary
B6: SKU | C6: Average of shipping Lead Time | D6: Average of Shipping Time | G6: Supplier Name | H6: AVG Defect Rate | L6: SKU | M6: cost | N6: profit | Q6: action | R6: quadrant | S6: Total Profit | T6: SKU Count | Y6: Action | Z6: Category | AA6: SKU | AB6: profit | AC6: Risk Score | AM6: Action | AN6: Profit
B7: SKU1 | C7: 30 | D7: 2 | G7: Supplier 1 | H7: 1.8 | L7: SKU10 | M7: 105.2 | N7: 15539.76 | Q7: Monitor | R7: High Profit - High Risk | S7: 1178227.5 | T7: 32 | Y7: Monitor | Z7: High Profit - High Risk | AA7: SKU40 | AB7: 75049.74 | AC7: 193.81 | AM7: Optimize | AN7: 63630.54
B8: SKU12 | C8: 30 | D8: 4 | G8: Supplier 4 | H8: 2.34 | L8: SKU13 | M8: 107.37 | N8: 3916.57 | Q8: Optimize | R8: Low Profit - Low Risk | S8: 63630.54 | T8: 14 | AA8: SKU55 | AB8: 55943.06 | AC8: 195.6 | AM8: Drop | AN8: 181899.44
B9: SKU14 | C9: 29 | D9: 5 | G9: Supplier 2 | H9: 2.36 | L9: SKU15 | M9: 99.54 | N9: 17248.41 | Q9: Scale | R9: High Profit - Low Risk | S9: 856510.98 | T9: 20 | AA9: SKU81 | AB9: 56338.21 | AC9: 99.35 | AM9: Scale | AN9: 856510.98
B10: SKU39 | C10: 29 | D10: 3 | G10: Supplier 3 | H10: 2.47 | L10: SKU16 | M10: 81.3 | N10: 2031.91 | AA10: SKU84 | AB10: 55024.31 | AC10: 290.61 | AM10: Monitor | AN10: 1178227.5
B11: SKU77 | C11: 28 | D11: 4 | G11: Supplier 5 | H11: 2.67 | L11: SKU19 | M11: 87.12 | N11: 9473.05 | AA11: SKU9 | AB11: 62680.29 | AC11: 219.14 | AM11: Grand Total | AN11: 2280268.5
B12: SKU42 | C12: 27 | D12: 4 | L12: SKU23 | M12: 101.53 | N12: 1589.28 | Z12: High Profit - High Risk Total | AB12: 305035.61 | AC12: 998.51
B13: SKU5 | C13: 27 | D13: 3 | L13: SKU25 | M13: 80.51 | N13: 5546.86 | Q13: Profit by Action | Z13: High Profit - Low Risk | AA13: SKU32 | AB13: 61826.67 | AC13: 91.46
B14: SKU9 | C14: 27 | D14: 1 | G14: Supplier Name | H14: Sku Count | L14: SKU28 | M14: 69.33 | N14: 875.2 | Q14: Total Profit | AA14: SKU52 | AB14: 80368.3 | AC14: 46.69
G15: Supplier 3 | H15: 15 | L15: SKU30 | M15: 60.59 | N15: 2562.89 | Q15: 2280268.5 | AA15: SKU58 | AB15: 53548.05 | AC15: 51.91
G16: Supplier 4 | H16: 18 | L16: SKU31 | M16: 62.93 | N16: 8479.43 | AA16: SKU80 | AB16: 79384.1 | AC16: 68.39
G17: Supplier 5 | H17: 18 | L17: SKU4 | M17: 95.96 | N17: 4089.63 | AA17: SKU95 | AB17: 52283.92 | AC17: 49.65
G18: Supplier 2 | H18: 22 | L18: SKU42 | M18: 103.95 | N18: 7108.07 | Z18: High Profit - Low Risk Total | AB18: 327411.04 | AC18: 308.1
G19: Supplier 1 | H19: 27 | L19: SKU45 | M19: 71.53 | N19: 739.29 | Y19: Monitor Total | AB19: 632446.65 | AC19: 1306.61
L20: SKU5 | M20: 61.21 | N20: 188.69 | Q20: Quadrant performance | Y20: Scale | Z20: High Profit - Low Risk | AA20: SKU0 | AB20: 55936.78 | AC20: 9.06
L21: SKU53 | M21: 84.36 | N21: 7258.28 | Q21: quadrant | R21: Total Profit | AA21: SKU11 | AB21: 86977.93 | AC21: 1.1
L22: SKU57 | M22: 76.94 | N22: 11105.81 | Q22: Low Profit - Low Risk | R22: 63630.54 | AA22: SKU14 | AB22: 55726.46 | AC22: 5.94
L23: SKU60 | M23: 91.59 | N23: 6379.06 | Q23: Low Profit - High Risk | R23: 181899.44 | AA23: SKU47 | AB23: 87069.35 | AC23: 12.94
L24: SKU61 | M24: 87.73 | N24: 5999.63 | Q24: High Profit - Low Risk | R24: 856510.98 | AA24: SKU91 | AB24: 56847.32 | AC24: 21.28
L25: SKU68 | M25: 98.31 | N25: 6084.58 | Q25: High Profit - High Risk | R25: 1178227.5 | Z25: High Profit - Low Risk Total | AB25: 342557.84 | AC25: 50.32
L26: SKU7 | M26: 101.81 | N26: 18198.46 | Y26: Scale Total | AB26: 342557.84 | AC26: 50.32
L27: SKU74 | M27: 85.82 | N27: 2779.87 | Y27: Drop | Z27: High Profit - High Risk | AA27: SKU1 | AB27: 10881.5 | AC27: 266.97
L28: SKU76 | M28: 71.38 | N28: 16583.84 | AA28: SKU19 | AB28: 9473.05 | AC28: 123.98
L29: SKU78 | M29: 79.59 | N29: 5886.72 | AA29: SKU36 | AB29: 9402.28 | AC29: 197.89
L30: SKU79 | M30: 64.37 | N30: 11232.92 | AA30: SKU57 | AB30: 11105.81 | AC30: 100.45
L31: SKU85 | M31: 78.18 | N31: 1845.9 | AA31: SKU75 | AB31: 9807.13 | AC31: 111.65
L32: SKU86 | M32: 76.06 | N32: 4383.53 | Z32: High Profit - High Risk Total | AB32: 50669.77 | AC32: 800.94
L33: SKU89 | M33: 56.53 | N33: 13043.32 | Z33: High Profit - Low Risk | AA33: SKU13 | AB33: 3916.57 | AC33: 65.24
L34: SKU90 | M34: 93.35 | N34: 4348.86 | AA34: SKU39 | AB34: 3351.87 | AC34: 90.02
L35: SKU92 | M35: 67.08 | N35: 13102.05 | AA35: SKU4 | AB35: 4089.63 | AC35: 50.33
L36: SKU94 | M36: 67.33 | N36: 2930.87 | AA36: SKU8 | AB36: 10292.81 | AC36: 81.3
L37: SKU97 | M37: 73.67 | N37: 144.95 | AA37: SKU86 | AB37: 4383.53 | AC37: 49.24
Z38: High Profit - Low Risk Total | AB38: 26034.41 | AC38: 336.13
Y39: Drop Total | AB39: 76704.18 | AC39: 1137.07
Y40: Optimize | Z40: High Profit - Low Risk | AA40: SKU17 | AB40: 10213.01 | AC40: 3.37
AA41: SKU43 | AB41: 6992.51 | AC41: 14.52
AA42: SKU53 | AB42: 7258.28 | AC42: 40.9
...

Sheet shipping_lead_time
A1: sku | B1: shipping_time | C1: shipping_lead_time
A2: SKU1 | B2: 2 | C2: 30
A3: SKU5 | B3: 3 | C3: 27
A4: SKU7 | B4: 1 | C4: 17
A5: SKU9 | B5: 1 | C5: 27
A6: SKU11 | B6: 1 | C6: 23
A7: SKU12 | B7: 4 | C7: 30
A8: SKU14 | B8: 5 | C8: 29
A9: SKU26 | B9: 4 | C9: 16
A10: SKU31 | B10: 4 | C10: 17
A11: SKU36 | B11: 3 | C11: 23
A12: SKU39 | B12: 3 | C12: 29
A13: SKU42 | B13: 4 | C13: 27
... A25: SKU93 | B25: 1 | C25: 17

Sheet defect_rate per supplier2
A1: supplier_name | B1: avg_defect_rate | C1: sku_count
A2: Supplier 5 | B2: 2.67 | C2: 18
A3: Supplier 3 | B3: 2.47 | C3: 15
A4: Supplier 2 | B4: 2.36 | C4: 22
A5: Supplier 4 | B5: 2.34 | C5: 18
A6: Supplier 1 | B6: 1.8 | C6: 27

Sheet cost vs profit analysis
A1: sku | B1: cost | C1: profit
A2: SKU10 | B2: 105.2 | C2: 15539.76
A3: SKU13 | B3: 107.37 | C3: 3916.57
A4: SKU15 | B4: 99.54 | C4: 17248.41
A5: SKU16 | B5: 81.3 | C5: 2031.91
A6: SKU19 | B6: 87.12 | C6: 9473.05
A7: SKU23 | B7: 101.53 | C7: 1589.28
A8: SKU25 | B8: 80.51 | C8: 5546.86
A9: SKU28 | B9: 69.33 | C9: 875.2
A10: SKU30 | B10: 60.59 | C10: 2562.89
A11: SKU31 | B11: 62.93 | C11: 8479.43
A12: SKU4 | B12: 95.96 | C12: 4089.63
A13: SKU42 | B13: 103.95 | C13: 7108.07
... A32: SKU97 | B32: 73.67 | C32: 144.95

Sheet cost vs profit_helper
A1: sku | B1: cost | C1: profit
A2: SKU7 | B2: 101.81 | C2: 18198.46
A3: SKU15 | B3: 99.54 | C3: 17248.41
A4: SKU76 | B4: 71.38 | C4: 16583.84
A5: SKU10 | B5: 105.2 | C5: 15539.76
A6: SKU92 | B6: 67.08 | C6: 13102.05
A7: SKU89 | B7: 56.53 | C7: 13043.32
A8: SKU79 | B8: 64.37 | C8: 11232.92
A9: SKU57 | B9: 76.94 | C9: 11105.81
A10: SKU19 | B10: 87.12 | C10: 9473.05
A11: SKU31 | B11: 62.93 | C11: 8479.43
A12: SKU53 | B12: 84.36 | C12: 7258.28
A13: SKU42 | B13: 103.95 | C13: 7108.07
... A32: SKU97 | B32: 73.67 | C32: 144.95

Sheet risk_tolerance
A1: sku | B1: total_profit | C1: risk_score | D1: risk_tolerance | E1: quadrant | F1: action | J1: AVG TOTAL_PROFIT | K1: AVG RISK SCORE | L1: TOTAL PROFIT | M1: SKU COUNT | O1: quadrant | P1: action
A2: SKU0 | B2: 55936.78 | C2: 9.06 | D2: High Profit - Low Risk | E2: {=_xlfn.IFS(AND(risk_tolerance[[#This Row],[total_profit]]>=($J$2*0.5),risk_tolerance[[#This Row],[risk_score]]>=($K$2*0.5)),"High Profit - High Risk", AND(risk_tolerance[[#This Row],[total_profit]]>=($J$2*0.5),risk_tolerance[[#This Row],[risk_score]]<($K$2*0.5)),"High Profit - Low Risk", AND(risk_tolerance[[#This Row],[total_profit]]<($J$2*0.5),risk_tolerance[[#This Row],[risk_score]]>=($K$2*0.5)),"Low Profit - High Risk", AND(risk_tolerance[[#This Row],[total_profit]]<($J$2*0.5),risk_tolerance[[#This Row],[risk_score]]<($K$2*0.5)),"Low Profit - Low Risk")} -> High Profit - Low Risk | F2: =_xlfn.XLOOKUP(risk_tolerance[[#This Row],[quadrant]],$O$1:$O$5,$P$1:$P$5,"N/A",0) -> Scale | J2: =AVERAGE(risk_tolerance[total_profit]) -> 22802.685 | K2: =AVERAGE(risk_tolerance[risk_score]) -> 92.188 | L2: =SUM(risk_tolerance[total_profit]) -> 2280268.5 | M2: =COUNTA(risk_tolerance[sku]) -> 100 | O2: High Profit - Low Risk | P2: Scale
A3: SKU1 | B3: 10881.5 | C3: 266.97 | D3: High Profit - High Risk | E3: {=_xlfn.IFS(AND(risk_tolerance[[#This Row],[total_profit]]>=($J$2*0.5),risk_tolerance[[#This Row],[risk_score]]>=($K$2*0.5)),"High Profit - High Risk", AND(risk_tolerance[[#This Row],[total_profit]]>=($J$2*0.5),risk_tolerance[[#This Row],[risk_score]]<($K$2*0.5)),"High Profit - Low Risk", AND(risk_tolerance[[#This Row],[total_profit]]<($J$2*0.5),risk_tolerance[[#This Row],[risk_score]]>=($K$2*0.5)),"Low Profit - High Risk", AND(risk_tolerance[[#This Row],[total_profit]]<($J$2*0.5),risk_tolerance[[#This Row],[risk_score]]<($K$2*0.5)),"Low Profit - Low Risk")} -> Low Profit - High Risk | F3: =_xlfn.XLOOKUP(risk_tolerance[[#This Row],[quadrant]],$O$1:$O$5,$P$1:$P$5,"N/A",0) -> Drop | O3: High Profit - High Risk | P3: Monitor
A4: SKU2 | B4: 51.81 | C4: 109.93 | D4: High Profit - High Risk | E4: {=_xlfn.IFS(AND(risk_tolerance[[#This Row],[total_profit]]>=($J$2*0.5),risk_tolerance[[#This Row],[risk_score]]>=($K$2*0.5)),"High Profit - High Risk", AND(risk_tolerance[[#This Row],[total_profit]]>=($J$2*0.5),risk_tolerance[[#This Row],[risk_score]]<($K$2*0.5)),"High Profit - Low Risk", AND(risk_tolerance[[#This Row],[total_profit]]<($J$2*0.5),risk_tolerance[[#This Row],[risk_score]]>=($K$2*0.5)),"Low Profit - High Risk", AND(risk_tolerance[[#This Row],[total_profit]]<($J$2*0.5),risk_tolerance[[#This Row],[risk_score]]<($K$2*0.5)),"Low Profit - Low Risk")} -> Low Profit - High Risk | F4: =_xlfn.XLOOKUP(risk_tolerance[[#This Row],[quadrant]],$O$1:$O$5,$P$1:$P$5,"N/A",0) -> Drop | O4: Low Profit - Low Risk | P4: Optimize
A5: SKU3 | B5: 5039.2 | C5: 204.11 | D5: High Profit - High Risk | E5: {=_xlfn.IFS(AND(risk_tolerance[[#This Row],[total_profit]]>=($J$2*0.5),risk_tolerance[[#This Row],[risk_score]]>=($K$2*0.5)),"High Profit - High Risk", AND(risk_tolerance[[#This Row],[total_profit]]>=($J$2*0.5),risk_tolerance[[#This Row],[risk_score]]<($K$2*0.5)),"High Profit - Low Risk", AND(risk_tolerance[[#This Row],[total_profit]]<($J$2*0.5),risk_tolerance[[#This Row],[risk_score]]>=($K$2*0.5)),"Low Profit - High Risk", AND(risk_tolerance[[#This Row],[total_profit]]<($J$2*0.5),risk_tolerance[[#This Row],[risk_score]]<($K$2*0.5)),"Low Profit - Low Risk")} -> Low Profit - High Risk | F5: =_xlfn.XLOOKUP(risk_tolerance[[#This Row],[quadrant]],$O$1:$O$5,$P$1:$P$5,"N/A",0) -> Drop | O5: Low Profit - High Risk | P5: Drop
A6: SKU4 | B6: 4089.63 | C6: 50.33 | D6: High Profit - Low Risk | E6: {=_xlfn.IFS(AND(risk_tolerance[[#This Row],[total_profit]]>=($J$2*0.5),risk_tolerance[[#This Row],[risk_score]]>=($K$2*0.5)),"High Profit - High Risk", AND(risk_tolerance[[#This Row],[total_profit]]>=($J$2*0.5),risk_tolerance[[#This Row],[risk_score]]<($K$2*0.5)),"High Profit - Low Risk", AND(risk_tolerance[[#This Row],[total_profit]]<($J$2*0.5),risk_tolerance[[#This Row],[risk_score]]>=($K$2*0.5)),"Low Profit - High Risk", AND(risk_tolerance[[#This Row],[total_profit]]<($J$2*0.5),risk_tolerance[[#This Row],[risk_score]]<($K$2*0.5)),"Low Profit - Low Risk")} -> Low Profit - High Risk | F6: =_xlfn.XLOOKUP(risk_tolerance[[#This Row],[quadrant]],$O$1:$O$5,$P$1:$P$5,"N/A",0) -> Drop
A7: SKU5 | B7: 188.69 | C7: 111.17 | D7: High Profit - High Risk | E7: {=_xlfn.IFS(AND(risk_tolerance[[#This Row],[total_profit]]>=($J$2*0.5),risk_tolerance[[#This Row],[risk_score]]>=($K$2*0.5)),"High Profit - High Risk", AND(risk_tolerance[[#This Row],[total_profit]]>=($J$2*0.5),risk_tolerance[[#This Row],[risk_score]]<($K$2*0.5)),"High Profit - Low Risk", AND(risk_tolerance[[#This Row],[total_profit]]<($J$2*0.5),risk_tolerance[[#This Row],[risk_score]]>=($K$2*0.5)),"Low Profit - High Risk", AND(risk_tolerance[[#This Row],[total_profit]]<($J$2*0.5),risk_tolerance[[#This Row],[risk_score]]<($K$2*0.5)),"Low Profit - Low Risk")} -> Low Profit - High Risk | F7: =_xlfn.XLOOKUP(risk_tolerance[[#This Row],[quadrant]],$O$1:$O$5,$P$1:$P$5,"N/A",0) -> Drop
A8: SKU6 | B8: 260.13 | C8: 37.03 | D8: High Profit - Low Risk | E8: {=_xlfn.IFS(AND(risk_tolerance[[#This Row],[total_profit]]>=($J$2*0.5),risk_tolerance[[#This Row],[risk_score]]>=($K$2*0.5)),"High Profit - High Risk", AND(risk_tolerance[[#This Row],[total_profit]]>=($J$2*0.5),risk_tolerance[[#This Row],[risk_score]]<($K$2*0.5)),"High Profit - Low Risk", AND(risk_tolerance[[#This Row],[total_profit]]<($J$2*0.5),risk_tolerance[[#This Row],[risk_score]]>=($K$2*0.5)),"Low Profit - High Risk", AND(risk_tolerance[[#This Row],[total_profit]]<($J$2*0.5),risk_tolerance[[#This Row],[risk_score]]<($K$2*0.5)),"Low Profit - Low Risk")} -> Low Profit - Low Risk | F8: =_xlfn.XLOOKUP(risk_tolerance[[#This Row],[quadrant]],$O$1:$O$5,$P$1:$P$5,"N/A",0) -> Optimize
A9: SKU7 | B9: 18198.46 | C9: 15.93 | D9: High Profit - Low Risk | E9: {=_xlfn.IFS(AND(risk_tolerance[[#This Row],[total_profit]]>=($J$2*0.5),risk_tolerance[[#This Row],[risk_score]]>=($K$2*0.5)),"High Profit - High Risk", AND(risk_tolerance[[#This Row],[total_profit]]>=($J$2*0.5),risk_tolerance[[#This Row],[risk_score]]<($K$2*0.5)),"High Profit - Low Risk", AND(risk_tolerance[[#This Row],[total_profit]]<($J$2*0.5),risk_tolerance[[#This Row],[risk_score]]>=($K$2*0.5)),"Low Profit - High Risk", AND(risk_tolerance[[#This Row],[total_profit]]<($J$2*0.5),risk_tolerance[[#This Row],[risk_score]]<($K$2*0.5)),"Low Profit - Low Risk")} -> High Profit - Low Risk | F9: =_xlfn.XLOOKUP(risk_tolerance[[#This Row],[quadrant]],$O$1:$O$5,$P$1:$P$5,"N/A",0) -> Scale
A10: SKU8 | B10: 10292.81 | C10: 81.3 | D10: High Profit - Low Risk | E10: {=_xlfn.IFS(AND(risk_tolerance[[#This Row],[total_profit]]>=($J$2*0.5),risk_tolerance[[#This Row],[risk_score]]>=($K$2*0.5)),"High Profit - High Risk", AND(risk_tolerance[[#This Row],[total_profit]]>=($J$2*0.5),risk_tolerance[[#This Row],[risk_score]]<($K$2*0.5)),"High Profit - Low Risk", AND(risk_tolerance[[#This Row],[total_profit]]<($J$2*0.5),risk_tolerance[[#This Row],[risk_score]]>=($K$2*0.5)),"Low Profit - High Risk", AND(risk_tolerance[[#This Row],[total_profit]]<($J$2*0.5),risk_tolerance[[#This Row],[risk_score]]<($K$2*0.5)),"Low Profit - Low Risk")} -> Low Profit - High Risk | F10: =_xlfn.XLOOKUP(risk_tolerance[[#This Row],[quadrant]],$O$1:$O$5,$P$1:$P$5,"N/A",0) -> Drop
A11: SKU9 | B11: 62680.29 | C11: 219.14 | D11: High Profit - High Risk | E11: {=_xlfn.IFS(AND(risk_tolerance[[#This Row],[total_profit]]>=($J$2*0.5),risk_tolerance[[#This Row],[risk_score]]>=($K$2*0.5)),"High Profit - High Risk", AND(risk_tolerance[[#This Row],[total_profit]]>=($J$2*0.5),risk_tolerance[[#This Row],[risk_score]]<($K$2*0.5)),"High Profit - Low Risk", AND(risk_tolerance[[#This Row],[total_profit]]<($J$2*0.5),risk_tolerance[[#This Row],[risk_score]]>=($K$2*0.5)),"Low Profit - High Risk", AND(risk_tolerance[[#This Row],[total_profit]]<($J$2*0.5),risk_tolerance[[#This Row],[risk_score]]<($K$2*0.5)),"Low Profit - Low Risk")} -> High Profit - High Risk | F11: =_xlfn.XLOOKUP(risk_tolerance[[#This Row],[quadrant]],$O$1:$O$5,$P$1:$P$5,"N/A",0) -> Monitor
A12: SKU10 | B12: 15539.76 | C12: 57 | D12: High Profit - Low Risk | E12: {=_xlfn.IFS(AND(risk_tolerance[[#This Row],[total_profit]]>=($J$2*0.5),risk_tolerance[[#This Row],[risk_score]]>=($K$2*0.5)),"High Profit - High Risk", AND(risk_tolerance[[#This Row],[total_profit]]>=($J$2*0.5),risk_tolerance[[#This Row],[risk_score]]<($K$2*0.5)),"High Profit - Low Risk", AND(risk_tolerance[[#This Row],[total_profit]]<($J$2*0.5),risk_tolerance[[#This Row],[risk_score]]>=($K$2*0.5)),"Low Profit - High Risk", AND(risk_tolerance[[#This Row],[total_profit]]<($J$2*0.5),risk_tolerance[[#This Row],[risk_score]]<($K$2*0.5)),"Low Profit - Low Risk")} -> High Profit - High Risk | F12: =_xlfn.XLOOKUP(risk_tolerance[[#This Row],[quadrant]],$O$1:$O$5,$P$1:$P$5,"N/A",0) -> Monitor
A13: SKU11 | B13: 86977.93 | C13: 1.1 | D13: High Profit - Low Risk | E13: {=_xlfn.IFS(AND(risk_tolerance[[#This Row],[total_profit]]>=($J$2*0.5),risk_tolerance[[#This Row],[risk_score]]>=($K$2*0.5)),"High Profit - High Risk", AND(risk_tolerance[[#This Row],[total_profit]]>=($J$2*0.5),risk_tolerance[[#This Row],[risk_score]]<($K$2*0.5)),"High Profit - Low Risk", AND(risk_tolerance[[#This Row],[total_profit]]<($J$2*0.5),risk_tolerance[[#This Row],[risk_score]]>=($K$2*0.5)),"Low Profit - High Risk", AND(risk_tolerance[[#This Row],[total_profit]]<($J$2*0.5),risk_tolerance[[#This Row],[risk_score]]<($K$2*0.5)),"Low Profit - Low Risk")} -> High Profit - Low Risk | F13: =_xlfn.XLOOKUP(risk_tolerance[[#This Row],[quadrant]],$O$1:$O$5,$P$1:$P$5,"N/A",0) -> Scale
A14: SKU12 | B14: 23894.05 | C14: 79.97 | D14: High Profit - Low Risk | E14: {=_xlfn.IFS(AND(risk_tolerance[[#This Row],[total_profit]]>=($J$2*0.5),risk_tolerance[[#This Row],[risk_score]]>=($K$2*0.5)),"High Profit - High Risk", AND(risk_tolerance[[#This Row],[total_profit]]>=($J$2*0.5),risk_tolerance[[#This Row],[risk_score]]<($K$2*0.5)),"High Profit - Low Risk", AND(risk_tolerance[[#This Row],[total_profit]]<($J$2*0.5),risk_tolerance[[#This Row],[risk_score]]>=($K$2*0.5)),"Low Profit - High Risk", AND(risk_tolerance[[#This Row],[total_profit]]<($J$2*0.5),risk_tolerance[[#This Row],[risk_score]]<($K$2*0.5)),"Low Profit - Low Risk")} -> High Profit - High Risk | F14: =_xlfn.XLOOKUP(risk_tolerance[[#This Row],[quadrant]],$O$1:$O$5,$P$1:$P$5,"N/A",0) -> Monitor
A15: SKU13 | B15: 3916.57 | C15: 65.24 | D15: High Profit - Low Risk | E15: {=_xlfn.IFS(AND(risk_tolerance[[#This Row],[total_profit]]>=($J$2*0.5),risk_tolerance[[#This Row],[risk_score]]>=($K$2*0.5)),"High Profit - High Risk", AND(risk_tolerance[[#This Row],[total_profit]]>=($J$2*0.5),risk_tolerance[[#This Row],[risk_score]]<($K$2*0.5)),"High Profit - Low Risk", AND(risk_tolerance[[#This Row],[total_profit]]<($J$2*0.5),risk_tolerance[[#This Row],[risk_score]]>=($K$2*0.5)),"Low Profit - High Risk", AND(risk_tolerance[[#This Row],[total_profit]]<($J$2*0.5),risk_tolerance[[#This Row],[risk_score]]<($K$2*0.5)),"Low Profit - Low Risk")} -> Low Profit - High Risk | F15: =_xlfn.XLOOKUP(risk_tolerance[[#This Row],[quadrant]],$O$1:$O$5,$P$1:$P$5,"N/A",0) -> Drop
A16: SKU14 | B16: 55726.46 | C16: 5.94 | D16: High Profit - Low Risk | E16: {=_xlfn.IFS(AND(risk_tolerance[[#This Row],[total_profit]]>=($J$2*0.5),risk_tolerance[[#This Row],[risk_score]]>=($K$2*0.5)),"High Profit - High Risk", AND(risk_tolerance[[#This Row],[total_profit]]>=($J$2*0.5),risk_tolerance[[#This Row],[risk_score]]<($K$2*0.5)),"High Profit - Low Risk", AND(risk_tolerance[[#This Row],[total_profit]]<($J$2*0.5),risk_tolerance[[#This Row],[risk_score]]>=($K$2*0.5)),"Low Profit - High Risk", AND(risk_tolerance[[#This Row],[total_profit]]<($J$2*0.5),risk_tolerance[[#This Row],[risk_score]]<($K$2*0.5)),"Low Profit - Low Risk")} -> High Profit - Low Risk | F16: =_xlfn.XLOOKUP(risk_tolerance[[#This Row],[quadrant]],$O$1:$O$5,$P$1:$P$5,"N/A",0) -> Scale
A17: SKU15 | B17: 17248.41 | C17: 65.67 | D17: High Profit - Low Risk | E17: {=_xlfn.IFS(AND(risk_tolerance[[#This Row],[total_profit]]>=($J$2*0.5),risk_tolerance[[#This Row],[risk_score]]>=($K$2*0.5)),"High Profit - High Risk", AND(risk_tolerance[[#This Row],[total_profit]]>=($J$2*0.5),risk_tolerance[[#This Row],[risk_score]]<($K$2*0.5)),"High Profit - Low Risk", AND(risk_tolerance[[#This Row],[total_profit]]<($J$2*0.5),risk_tolerance[[#This Row],[risk_score]]>=($K$2*0.5)),"Low Profit - High Risk", AND(risk_tolerance[[#This Row],[total_profit]]<($J$2*0.5),risk_tolerance[[#This Row],[risk_score]]<($K$2*0.5)),"Low Profit - Low Risk")} -> High Profit - High Risk | F17: =_xlfn.XLOOKUP(risk_tolerance[[#This Row],[quadrant]],$O$1:$O$5,$P$1:$P$5,"N/A",0) -> Monitor
... A101: SKU99 | B101: 42921.3 | C101: 14.88 | D101: High Profit - Low Risk | E101: {=_xlfn.IFS(AND(risk_tolerance[[#This Row],[total_profit]]>=($J$2*0.5),risk_tolerance[[#This Row],[risk_score]]>=($K$2*0.5)),"High Profit - High Risk", AND(risk_tolerance[[#This Row],[total_profit]]>=($J$2*0.5),risk_tolerance[[#This Row],[risk_score]]<($K$2*0.5)),"High Profit - Low Risk", AND(risk_tolerance[[#This Row],[total_profit]]<($J$2*0.5),risk_tolerance[[#This Row],[risk_score]]>=($K$2*0.5)),"Low Profit - High Risk", AND(risk_tolerance[[#This Row],[total_profit]]<($J$2*0.5),risk_tolerance[[#This Row],[risk_score]]<($K$2*0.5)),"Low Profit - Low Risk")} -> High Profit - Low Risk | F101: =_xlfn.XLOOKUP(risk_tolerance[[#This Row],[quadrant]],$O$1:$O$5,$P$1:$P$5,"N/A",0) -> Scale

Sheet profit_vs_risk scenario5
A1: sku | B1: profit | C1: risk_score | D1: Category | E1: priority_score | F1: Rank_score | G1: Action | L1: AVG PRIORITY SCORE
A2: SKU11 | B2: 86977.93 | C2: 1.1 | D2: High Profit - Low Risk | E2: 79070.85 | F2: 1 | G2: =_xlfn.XLOOKUP(profit_vs_risk_scenario5[[#This Row],[sku]],'risk_tolerance'!A:A,'risk_tolerance'!F:F,"N/A",0) -> Scale | L2: =AVERAGE(profit_vs_risk_scenario5[priority_score]) -> 2392.7221
A3: SKU21 | B3: 50953.44 | C3: 0.93 | D3: High Profit - Low Risk | E3: 54788.65 | F3: 2 | G3: =_xlfn.XLOOKUP(profit_vs_risk_scenario5[[#This Row],[sku]],'risk_tolerance'!A:A,'risk_tolerance'!F:F,"N/A",0) -> Scale
A4: SKU41 | B4: 55005.88 | C4: 2.04 | D4: High Profit - Low Risk | E4: 26963.67 | F4: 3 | G4: =_xlfn.XLOOKUP(profit_vs_risk_scenario5[[#This Row],[sku]],'risk_tolerance'!A:A,'risk_tolerance'!F:F,"N/A",0) -> Scale
A5: SKU67 | B5: 45002.33 | C5: 3.69 | D5: High Profit - Low Risk | E5: 12195.75 | F5: 4 | G5: =_xlfn.XLOOKUP(profit_vs_risk_scenario5[[#This Row],[sku]],'risk_tolerance'!A:A,'risk_tolerance'!F:F,"N/A",0) -> Scale
A6: SKU14 | B6: 55726.46 | C6: 5.94 | D6: High Profit - Low Risk | E6: 9381.56 | F6: 5 | G6: =_xlfn.XLOOKUP(profit_vs_risk_scenario5[[#This Row],[sku]],'risk_tolerance'!A:A,'risk_tolerance'!F:F,"N/A",0) -> Scale
A7: SKU47 | B7: 87069.35 | C7: 12.94 | D7: High Profit - Low Risk | E7: 6728.7 | F7: 6 | G7: =_xlfn.XLOOKUP(profit_vs_risk_scenario5[[#This Row],[sku]],'risk_tolerance'!A:A,'risk_tolerance'!F:F,"N/A",0) -> Scale
A8: SKU0 | B8: 55936.78 | C8: 9.06 | D8: High Profit - Low Risk | E8: 6174.04 | F8: 7 | G8: =_xlfn.XLOOKUP(profit_vs_risk_scenario5[[#This Row],[sku]],'risk_tolerance'!A:A,'risk_tolerance'!F:F,"N/A",0) -> Scale
A9: SKU38 | B9: 36698.36 | C9: 9.81 | D9: High Profit - Low Risk | E9: 3740.91 | F9: 8 | G9: =_xlfn.XLOOKUP(profit_vs_risk_scenario5[[#This Row],[sku]],'risk_tolerance'!A:A,'risk_tolerance'!F:F,"N/A",0) -> Scale
A10: SKU17 | B10: 10213.01 | C10: 3.37 | D10: High Profit - Low Risk | E10: 3030.57 | F10: 9 | G10: =_xlfn.XLOOKUP(profit_vs_risk_scenario5[[#This Row],[sku]],'risk_tolerance'!A:A,'risk_tolerance'!F:F,"N/A",0) -> Optimize
A11: SKU99 | B11: 42921.3 | C11: 14.88 | D11: High Profit - Low Risk | E11: 2884.5 | F11: 10 | G11: =_xlfn.XLOOKUP(profit_vs_risk_scenario5[[#This Row],[sku]],'risk_tolerance'!A:A,'risk_tolerance'!F:F,"N/A",0) -> Scale
A12: SKU91 | B12: 56847.32 | C12: 21.28 | D12: High Profit - Low Risk | E12: 2671.4 | F12: 11 | G12: =_xlfn.XLOOKUP(profit_vs_risk_scenario5[[#This Row],[sku]],'risk_tolerance'!A:A,'risk_tolerance'!F:F,"N/A",0) -> Scale
A13: SKU79 | B13: 11232.92 | C13: 5.14 | D13: High Profit - Low Risk | E13: 2185.39 | F13: 12 | G13: =_xlfn.XLOOKUP(profit_vs_risk_scenario5[[#This Row],[sku]],'risk_tolerance'!A:A,'risk_tolerance'!F:F,"N/A",0) -> Optimize
A14: SKU59 | B14: 30883.75 | C14: 15.2 | D14: High Profit - Low Risk | E14: 2031.83 | F14: 13 | G14: =_xlfn.XLOOKUP(profit_vs_risk_scenario5[[#This Row],[sku]],'risk_tolerance'!A:A,'risk_tolerance'!F:F,"N/A",0) -> Scale
... A101: SKU2 | B101: 51.81 | C101: 109.93 | D101: High Profit - High Risk | E101: 0.47 | F101: 100 | G101: =_xlfn.XLOOKUP(profit_vs_risk_scenario5[[#This Row],[sku]],'risk_tolerance'!A:A,'risk_tolerance'!F:F,"N/A",0) -> Drop
